using System;
using System.Linq;
using ReqTrack.Domain.Core.Exceptions;
using ReqTrack.Domain.Core.Repositories;
using ReqTrack.Domain.Core.Security;
using ReqTrack.Domain.Core.UseCases.Boundary.Extensions;
using ReqTrack.Domain.Core.UseCases.Boundary.Interfaces;
using ReqTrack.Domain.Core.UseCases.Boundary.Responses;
using ReqTrack.Domain.Core.UseCases.Exceptions;

namespace ReqTrack.Domain.Core.UseCases.Users.ViewProfile
{
    public class ViewProfileUseCase : IUseCase<ViewProfileRequest, ViewProfileResponse>
    {
        private readonly ISecurityGateway _securityGateway;

        private readonly IUserRepository _userRepository;

        public ViewProfileUseCase(ISecurityGateway securityGateway, IUserRepository userRepository)
        {
            _securityGateway = securityGateway;
            _userRepository = userRepository;
        }

        public void Execute(IUseCaseOutput<ViewProfileResponse> output, ViewProfileRequest request)
        {
            try
            {
                request.ValidateAndThrowOnInvalid();

                var user = _userRepository.ReadUser(request.UserId, true);

                output.Accept(new ViewProfileResponse
                {
                    UserId = user.Id,
                    UserName = user.UserName,
                    DisplayName = user.DisplayName,
                    Projects = user.Projects.Select(x => new Project
                    {
                        Identifier = x.Id,
                        Name = x.Name,
                    }),
                });
            }
            catch (RequestValidationException e)
            {
                output.Accept(new ValidationErrorResponse
                {
                    Message = $"Invalid request. {e.Message}",
                    ValidationErrors = e.ValidationErrors,
                });
            }
            catch (EntityNotFoundException e)
            {
                output.Accept(new FailureResponse
                {
                    Message = $"User not found. {e.Message}",
                });
            }
            catch (Exception e)
            {
                output.Accept(new FailureResponse
                {
                    Message = $"Tehnical error happend. {e.Message}",
                });
            }
        }
    }
}
